[2024-02-18 14:44:44,615] 160 numexpr.utils - INFO -NumExpr defaulting to 4 threads.
[2024-02-18 14:45:23,238] 38 root - INFO -starting data ingestion
[2024-02-18 14:45:23,347] 41 root - INFO -performed train test split on dataframe
[2024-02-18 14:45:23,347] 42 root - INFO -exited split_data as train test split
[2024-02-18 14:45:23,350] 47 root - INFO -exporting train and test file path
[2024-02-18 14:45:23,397] 52 root - INFO -exported train and test file path
[2024-02-18 14:45:23,398] 41 root - INFO -Data ingestion completed and artifact: DataIngestionArtifact(trained_file_path='artifact\\02_18_2024_14_44_43\\data_ingestion\\ingested\\train.csv')
[2024-02-18 14:45:23,503] 28 root - INFO -Required number of columns: 5
[2024-02-18 14:45:23,503] 29 root - INFO -Data frame has columns: 5
[2024-02-18 14:45:23,503] 48 root - INFO -Missing numerical columns: [[]]
[2024-02-18 14:45:23,504] 136 root - INFO -Data validation artifact: DataValidationArtifact(validation_status=True, valid_train_file_path='artifact\\02_18_2024_14_44_43\\data_ingestion\\ingested\\train.csv', invalid_train_file_path=None, invalid_test_file_path=None, drift_report_file_path='artifact\\02_18_2024_14_44_43\\data_validation\\drift_report\\report.yaml')
[2024-02-18 14:45:25,275] 48 root - INFO -Entered the save_object method of MainUtils class
[2024-02-18 14:45:25,279] 52 root - INFO -Exited the save_object method of MainUtils class
[2024-02-18 14:45:25,279] 48 root - INFO -Entered the save_object method of MainUtils class
[2024-02-18 14:45:25,282] 52 root - INFO -Exited the save_object method of MainUtils class
[2024-02-18 14:45:25,314] 216 root - INFO -Data transformation artifact: DataTransformationArtifact(transformed_object_file_path='artifact\\02_18_2024_14_44_43\\data_transformation\\transformed_object\\preprocessing.pkl', transformed_object2_file_path='artifact\\02_18_2024_14_44_43\\data_transformation\\transformed_object\\preprocessing1.pkl', transformed_train_file_path='artifact\\02_18_2024_14_44_43\\data_transformation\\transformed\\train.npy', transformed_test_file_path='artifact\\02_18_2024_14_44_43\\data_transformation\\transformed\\test.npy', transformed_train_file_path1='artifact\\02_18_2024_14_44_43\\data_transformation\\transformed_object\\train.csv')
[2024-02-18 14:45:25,520] 48 root - INFO -Entered the save_object method of MainUtils class
[2024-02-18 14:45:25,533] 52 root - INFO -Exited the save_object method of MainUtils class
[2024-02-18 14:45:25,533] 48 root - INFO -Entered the save_object method of MainUtils class
[2024-02-18 14:45:25,545] 52 root - INFO -Exited the save_object method of MainUtils class
[2024-02-18 14:45:25,546] 95 root - INFO -Model trainer artifact: ModelTrainerArtifact(trained_model_file_path='artifact\\02_18_2024_14_44_43\\model_trainer\\trained_model\\model.pkl', train_metric_artifact=regressionMetricArtifact(f1_score=0.8723404255319148, precision_score=0.9111111111111111, recall_score=0.8367346938775511), test_metric_artifact=regressionMetricArtifact(f1_score=0.4761904761904762, precision_score=0.4166666666666667, recall_score=0.5555555555555556))
[2024-02-18 14:45:25,575] 75 root - INFO -Model evaluation artifact: ModelEvaluationArtifact(is_model_accepted=True, improved_accuracy=None, best_model_path=None, trained_model_path='artifact\\02_18_2024_14_44_43\\model_trainer\\trained_model\\model.pkl', train_model_metric_artifact=regressionMetricArtifact(f1_score=0.4761904761904762, precision_score=0.4166666666666667, recall_score=0.5555555555555556), best_model_metric_artifact=None)
[2024-02-18 14:45:25,873] 241 django.request - ERROR -Internal Server Error: /prediction
Traceback (most recent call last):
  File "C:\Users\DELL\Anaconda3\lib\site-packages\django\core\handlers\exception.py", line 55, in inner
    response = get_response(request)
  File "C:\Users\DELL\Anaconda3\lib\site-packages\django\core\handlers\base.py", line 197, in _get_response
    response = wrapped_callback(request, *callback_args, **callback_kwargs)
  File "C:\Users\DELL\PycharmProjects\django\myproject\trade\views.py", line 41, in prediction
    return render(request, 'trade/prediction.html',output)
  File "C:\Users\DELL\Anaconda3\lib\site-packages\django\shortcuts.py", line 24, in render
    content = loader.render_to_string(template_name, context, request, using=using)
  File "C:\Users\DELL\Anaconda3\lib\site-packages\django\template\loader.py", line 62, in render_to_string
    return template.render(context, request)
  File "C:\Users\DELL\Anaconda3\lib\site-packages\django\template\backends\django.py", line 57, in render
    context = make_context(
  File "C:\Users\DELL\Anaconda3\lib\site-packages\django\template\context.py", line 278, in make_context
    raise TypeError(
TypeError: context must be a dict rather than set.
[2024-02-18 14:46:18,185] 266 django.utils.autoreload - INFO -C:\Users\DELL\PycharmProjects\django\myproject\trade\views.py changed, reloading.
