[2024-02-18 15:22:26,636] 160 numexpr.utils - INFO -NumExpr defaulting to 4 threads.
[2024-02-18 15:23:12,561] 241 django.request - WARNING -Not Found: /prediction/
[2024-02-18 15:23:17,533] 241 django.request - WARNING -Not Found: /prediction/
[2024-02-18 15:23:22,931] 241 django.request - WARNING -Not Found: /prediction/
[2024-02-18 15:23:27,944] 241 django.request - WARNING -Not Found: /prediction/
[2024-02-18 15:23:32,359] 38 root - INFO -starting data ingestion
[2024-02-18 15:23:32,475] 41 root - INFO -performed train test split on dataframe
[2024-02-18 15:23:32,476] 42 root - INFO -exited split_data as train test split
[2024-02-18 15:23:32,478] 47 root - INFO -exporting train and test file path
[2024-02-18 15:23:32,528] 52 root - INFO -exported train and test file path
[2024-02-18 15:23:32,529] 41 root - INFO -Data ingestion completed and artifact: DataIngestionArtifact(trained_file_path='artifact\\02_18_2024_15_22_25\\data_ingestion\\ingested\\train.csv')
[2024-02-18 15:23:32,637] 28 root - INFO -Required number of columns: 5
[2024-02-18 15:23:32,638] 29 root - INFO -Data frame has columns: 5
[2024-02-18 15:23:32,638] 48 root - INFO -Missing numerical columns: [[]]
[2024-02-18 15:23:32,638] 136 root - INFO -Data validation artifact: DataValidationArtifact(validation_status=True, valid_train_file_path='artifact\\02_18_2024_15_22_25\\data_ingestion\\ingested\\train.csv', invalid_train_file_path=None, invalid_test_file_path=None, drift_report_file_path='artifact\\02_18_2024_15_22_25\\data_validation\\drift_report\\report.yaml')
[2024-02-18 15:23:33,468] 241 django.request - WARNING -Not Found: /prediction/
[2024-02-18 15:23:34,395] 48 root - INFO -Entered the save_object method of MainUtils class
[2024-02-18 15:23:34,400] 52 root - INFO -Exited the save_object method of MainUtils class
[2024-02-18 15:23:34,400] 48 root - INFO -Entered the save_object method of MainUtils class
[2024-02-18 15:23:34,403] 52 root - INFO -Exited the save_object method of MainUtils class
[2024-02-18 15:23:34,434] 216 root - INFO -Data transformation artifact: DataTransformationArtifact(transformed_object_file_path='artifact\\02_18_2024_15_22_25\\data_transformation\\transformed_object\\preprocessing.pkl', transformed_object2_file_path='artifact\\02_18_2024_15_22_25\\data_transformation\\transformed_object\\preprocessing1.pkl', transformed_train_file_path='artifact\\02_18_2024_15_22_25\\data_transformation\\transformed\\train.npy', transformed_test_file_path='artifact\\02_18_2024_15_22_25\\data_transformation\\transformed\\test.npy', transformed_train_file_path1='artifact\\02_18_2024_15_22_25\\data_transformation\\transformed_object\\train.csv')
[2024-02-18 15:23:34,606] 48 root - INFO -Entered the save_object method of MainUtils class
[2024-02-18 15:23:34,619] 52 root - INFO -Exited the save_object method of MainUtils class
[2024-02-18 15:23:34,619] 48 root - INFO -Entered the save_object method of MainUtils class
[2024-02-18 15:23:34,631] 52 root - INFO -Exited the save_object method of MainUtils class
[2024-02-18 15:23:34,632] 95 root - INFO -Model trainer artifact: ModelTrainerArtifact(trained_model_file_path='artifact\\02_18_2024_15_22_25\\model_trainer\\trained_model\\model.pkl', train_metric_artifact=regressionMetricArtifact(f1_score=0.8723404255319148, precision_score=0.9111111111111111, recall_score=0.8367346938775511), test_metric_artifact=regressionMetricArtifact(f1_score=0.4761904761904762, precision_score=0.4166666666666667, recall_score=0.5555555555555556))
[2024-02-18 15:23:34,861] 113 root - INFO -Model evaluation artifact: ModelEvaluationArtifact(is_model_accepted=False, improved_accuracy=0.0, best_model_path='saved_models\\1708249304\\model.pkl', trained_model_path='artifact\\02_18_2024_15_22_25\\model_trainer\\trained_model\\model.pkl', train_model_metric_artifact=regressionMetricArtifact(f1_score=0.8723404255319148, precision_score=0.9111111111111111, recall_score=0.8367346938775511), best_model_metric_artifact=regressionMetricArtifact(f1_score=0.8723404255319148, precision_score=0.9111111111111111, recall_score=0.8367346938775511))
[2024-02-18 15:23:35,121] 241 django.request - ERROR -Internal Server Error: /prediction
Traceback (most recent call last):
  File "C:\Users\DELL\PycharmProjects\django\myproject\src\pipeline\training_pipeline.py", line 128, in run_pipeline
    raise Exception("Trained model is not better than the best model")
Exception: Trained model is not better than the best model

During handling of the above exception, another exception occurred:

Traceback (most recent call last):
  File "C:\Users\DELL\Anaconda3\lib\site-packages\django\core\handlers\exception.py", line 55, in inner
    response = get_response(request)
  File "C:\Users\DELL\Anaconda3\lib\site-packages\django\core\handlers\base.py", line 197, in _get_response
    response = wrapped_callback(request, *callback_args, **callback_kwargs)
  File "C:\Users\DELL\PycharmProjects\django\myproject\trade\views.py", line 43, in prediction
    train_pipeline.run_pipeline()
  File "C:\Users\DELL\PycharmProjects\django\myproject\src\pipeline\training_pipeline.py", line 136, in run_pipeline
    raise SensorException(e,sys)
src.exception.SensorException: Error occurred python script name [C:\Users\DELL\PycharmProjects\django\myproject\src\pipeline\training_pipeline.py] line number [128] error message [Trained model is not better than the best model]
[2024-02-18 15:24:09,457] 241 django.request - WARNING -Not Found: /prediction/
[2024-02-18 15:24:14,454] 241 django.request - WARNING -Not Found: /prediction/
[2024-02-18 15:24:19,936] 241 django.request - WARNING -Not Found: /prediction/
[2024-02-18 15:24:24,939] 241 django.request - WARNING -Not Found: /prediction/
[2024-02-18 15:24:27,103] 38 root - INFO -starting data ingestion
[2024-02-18 15:24:27,333] 41 root - INFO -performed train test split on dataframe
[2024-02-18 15:24:27,333] 42 root - INFO -exited split_data as train test split
[2024-02-18 15:24:27,334] 47 root - INFO -exporting train and test file path
[2024-02-18 15:24:27,391] 52 root - INFO -exported train and test file path
[2024-02-18 15:24:27,392] 41 root - INFO -Data ingestion completed and artifact: DataIngestionArtifact(trained_file_path='artifact\\02_18_2024_15_22_25\\data_ingestion\\ingested\\train.csv')
[2024-02-18 15:24:27,505] 28 root - INFO -Required number of columns: 5
[2024-02-18 15:24:27,506] 29 root - INFO -Data frame has columns: 5
[2024-02-18 15:24:27,506] 48 root - INFO -Missing numerical columns: [[]]
[2024-02-18 15:24:27,506] 136 root - INFO -Data validation artifact: DataValidationArtifact(validation_status=True, valid_train_file_path='artifact\\02_18_2024_15_22_25\\data_ingestion\\ingested\\train.csv', invalid_train_file_path=None, invalid_test_file_path=None, drift_report_file_path='artifact\\02_18_2024_15_22_25\\data_validation\\drift_report\\report.yaml')
[2024-02-18 15:24:29,362] 48 root - INFO -Entered the save_object method of MainUtils class
[2024-02-18 15:24:29,367] 52 root - INFO -Exited the save_object method of MainUtils class
[2024-02-18 15:24:29,367] 48 root - INFO -Entered the save_object method of MainUtils class
[2024-02-18 15:24:29,369] 52 root - INFO -Exited the save_object method of MainUtils class
[2024-02-18 15:24:29,400] 216 root - INFO -Data transformation artifact: DataTransformationArtifact(transformed_object_file_path='artifact\\02_18_2024_15_22_25\\data_transformation\\transformed_object\\preprocessing.pkl', transformed_object2_file_path='artifact\\02_18_2024_15_22_25\\data_transformation\\transformed_object\\preprocessing1.pkl', transformed_train_file_path='artifact\\02_18_2024_15_22_25\\data_transformation\\transformed\\train.npy', transformed_test_file_path='artifact\\02_18_2024_15_22_25\\data_transformation\\transformed\\test.npy', transformed_train_file_path1='artifact\\02_18_2024_15_22_25\\data_transformation\\transformed_object\\train.csv')
[2024-02-18 15:24:29,551] 48 root - INFO -Entered the save_object method of MainUtils class
[2024-02-18 15:24:29,562] 52 root - INFO -Exited the save_object method of MainUtils class
[2024-02-18 15:24:29,562] 48 root - INFO -Entered the save_object method of MainUtils class
[2024-02-18 15:24:29,575] 52 root - INFO -Exited the save_object method of MainUtils class
[2024-02-18 15:24:29,575] 95 root - INFO -Model trainer artifact: ModelTrainerArtifact(trained_model_file_path='artifact\\02_18_2024_15_22_25\\model_trainer\\trained_model\\model.pkl', train_metric_artifact=regressionMetricArtifact(f1_score=0.8723404255319148, precision_score=0.9111111111111111, recall_score=0.8367346938775511), test_metric_artifact=regressionMetricArtifact(f1_score=0.4761904761904762, precision_score=0.4166666666666667, recall_score=0.5555555555555556))
[2024-02-18 15:24:29,606] 75 root - INFO -Model evaluation artifact: ModelEvaluationArtifact(is_model_accepted=True, improved_accuracy=None, best_model_path=None, trained_model_path='artifact\\02_18_2024_15_22_25\\model_trainer\\trained_model\\model.pkl', train_model_metric_artifact=regressionMetricArtifact(f1_score=0.4761904761904762, precision_score=0.4166666666666667, recall_score=0.5555555555555556), best_model_metric_artifact=None)
[2024-02-18 15:24:29,942] 241 django.request - WARNING -Not Found: /prediction/
[2024-02-18 15:24:34,931] 241 django.request - WARNING -Not Found: /prediction/
[2024-02-18 15:24:39,453] 241 django.request - WARNING -Not Found: /prediction/
[2024-02-18 15:24:43,445] 38 root - INFO -starting data ingestion
[2024-02-18 15:24:43,548] 41 root - INFO -performed train test split on dataframe
[2024-02-18 15:24:43,549] 42 root - INFO -exited split_data as train test split
[2024-02-18 15:24:43,550] 47 root - INFO -exporting train and test file path
[2024-02-18 15:24:43,595] 52 root - INFO -exported train and test file path
[2024-02-18 15:24:43,596] 41 root - INFO -Data ingestion completed and artifact: DataIngestionArtifact(trained_file_path='artifact\\02_18_2024_15_22_25\\data_ingestion\\ingested\\train.csv')
[2024-02-18 15:24:43,697] 28 root - INFO -Required number of columns: 5
[2024-02-18 15:24:43,698] 29 root - INFO -Data frame has columns: 5
[2024-02-18 15:24:43,698] 48 root - INFO -Missing numerical columns: [[]]
[2024-02-18 15:24:43,698] 136 root - INFO -Data validation artifact: DataValidationArtifact(validation_status=True, valid_train_file_path='artifact\\02_18_2024_15_22_25\\data_ingestion\\ingested\\train.csv', invalid_train_file_path=None, invalid_test_file_path=None, drift_report_file_path='artifact\\02_18_2024_15_22_25\\data_validation\\drift_report\\report.yaml')
[2024-02-18 15:24:44,551] 241 django.request - WARNING -Not Found: /prediction/
[2024-02-18 15:24:45,459] 48 root - INFO -Entered the save_object method of MainUtils class
[2024-02-18 15:24:45,462] 52 root - INFO -Exited the save_object method of MainUtils class
[2024-02-18 15:24:45,463] 48 root - INFO -Entered the save_object method of MainUtils class
[2024-02-18 15:24:45,466] 52 root - INFO -Exited the save_object method of MainUtils class
[2024-02-18 15:24:45,493] 216 root - INFO -Data transformation artifact: DataTransformationArtifact(transformed_object_file_path='artifact\\02_18_2024_15_22_25\\data_transformation\\transformed_object\\preprocessing.pkl', transformed_object2_file_path='artifact\\02_18_2024_15_22_25\\data_transformation\\transformed_object\\preprocessing1.pkl', transformed_train_file_path='artifact\\02_18_2024_15_22_25\\data_transformation\\transformed\\train.npy', transformed_test_file_path='artifact\\02_18_2024_15_22_25\\data_transformation\\transformed\\test.npy', transformed_train_file_path1='artifact\\02_18_2024_15_22_25\\data_transformation\\transformed_object\\train.csv')
[2024-02-18 15:24:45,859] 48 root - INFO -Entered the save_object method of MainUtils class
[2024-02-18 15:24:45,875] 52 root - INFO -Exited the save_object method of MainUtils class
[2024-02-18 15:24:45,875] 48 root - INFO -Entered the save_object method of MainUtils class
[2024-02-18 15:24:45,893] 52 root - INFO -Exited the save_object method of MainUtils class
[2024-02-18 15:24:45,894] 95 root - INFO -Model trainer artifact: ModelTrainerArtifact(trained_model_file_path='artifact\\02_18_2024_15_22_25\\model_trainer\\trained_model\\model.pkl', train_metric_artifact=regressionMetricArtifact(f1_score=0.8723404255319148, precision_score=0.9111111111111111, recall_score=0.8367346938775511), test_metric_artifact=regressionMetricArtifact(f1_score=0.4761904761904762, precision_score=0.4166666666666667, recall_score=0.5555555555555556))
[2024-02-18 15:24:46,206] 113 root - INFO -Model evaluation artifact: ModelEvaluationArtifact(is_model_accepted=False, improved_accuracy=0.0, best_model_path='saved_models\\1708250070\\model.pkl', trained_model_path='artifact\\02_18_2024_15_22_25\\model_trainer\\trained_model\\model.pkl', train_model_metric_artifact=regressionMetricArtifact(f1_score=0.8723404255319148, precision_score=0.9111111111111111, recall_score=0.8367346938775511), best_model_metric_artifact=regressionMetricArtifact(f1_score=0.8723404255319148, precision_score=0.9111111111111111, recall_score=0.8367346938775511))
[2024-02-18 15:24:46,458] 241 django.request - ERROR -Internal Server Error: /prediction
Traceback (most recent call last):
  File "C:\Users\DELL\PycharmProjects\django\myproject\src\pipeline\training_pipeline.py", line 128, in run_pipeline
    raise Exception("Trained model is not better than the best model")
Exception: Trained model is not better than the best model

During handling of the above exception, another exception occurred:

Traceback (most recent call last):
  File "C:\Users\DELL\Anaconda3\lib\site-packages\django\core\handlers\exception.py", line 55, in inner
    response = get_response(request)
  File "C:\Users\DELL\Anaconda3\lib\site-packages\django\core\handlers\base.py", line 197, in _get_response
    response = wrapped_callback(request, *callback_args, **callback_kwargs)
  File "C:\Users\DELL\PycharmProjects\django\myproject\trade\views.py", line 44, in prediction
    progress = train_pipeline.run_pipeline(progress_callback=update_progress)
  File "C:\Users\DELL\PycharmProjects\django\myproject\src\pipeline\training_pipeline.py", line 136, in run_pipeline
    raise SensorException(e,sys)
src.exception.SensorException: Error occurred python script name [C:\Users\DELL\PycharmProjects\django\myproject\src\pipeline\training_pipeline.py] line number [128] error message [Trained model is not better than the best model]
