[2024-02-19 23:55:06,923] 160 numexpr.utils - INFO -NumExpr defaulting to 4 threads.
[2024-02-19 23:55:18,429] 241 django.request - ERROR -Internal Server Error: /cad
Traceback (most recent call last):
  File "C:\Users\DELL\Anaconda3\lib\site-packages\django\core\handlers\exception.py", line 55, in inner
    response = get_response(request)
  File "C:\Users\DELL\Anaconda3\lib\site-packages\django\core\handlers\base.py", line 197, in _get_response
    response = wrapped_callback(request, *callback_args, **callback_kwargs)
  File "C:\Users\DELL\PycharmProjects\django\myproject\trade\views.py", line 445, in candlestick_chart_view
    df=pd.read_csv('myproject/1RELIANCE3.csv')
  File "C:\Users\DELL\Anaconda3\lib\site-packages\pandas\util\_decorators.py", line 211, in wrapper
    return func(*args, **kwargs)
  File "C:\Users\DELL\Anaconda3\lib\site-packages\pandas\util\_decorators.py", line 331, in wrapper
    return func(*args, **kwargs)
  File "C:\Users\DELL\Anaconda3\lib\site-packages\pandas\io\parsers\readers.py", line 950, in read_csv
    return _read(filepath_or_buffer, kwds)
  File "C:\Users\DELL\Anaconda3\lib\site-packages\pandas\io\parsers\readers.py", line 605, in _read
    parser = TextFileReader(filepath_or_buffer, **kwds)
  File "C:\Users\DELL\Anaconda3\lib\site-packages\pandas\io\parsers\readers.py", line 1442, in __init__
    self._engine = self._make_engine(f, self.engine)
  File "C:\Users\DELL\Anaconda3\lib\site-packages\pandas\io\parsers\readers.py", line 1735, in _make_engine
    self.handles = get_handle(
  File "C:\Users\DELL\Anaconda3\lib\site-packages\pandas\io\common.py", line 856, in get_handle
    handle = open(
FileNotFoundError: [Errno 2] No such file or directory: 'myproject/1RELIANCE3.csv'
[2024-02-19 23:56:05,931] 266 django.utils.autoreload - INFO -C:\Users\DELL\PycharmProjects\django\myproject\trade\views.py changed, reloading.
