[2024-02-18 15:58:57,754] 160 numexpr.utils - INFO -NumExpr defaulting to 4 threads.
[2024-02-18 15:59:21,059] 38 root - INFO -starting data ingestion
[2024-02-18 15:59:21,165] 41 root - INFO -performed train test split on dataframe
[2024-02-18 15:59:21,166] 42 root - INFO -exited split_data as train test split
[2024-02-18 15:59:21,168] 47 root - INFO -exporting train and test file path
[2024-02-18 15:59:21,213] 52 root - INFO -exported train and test file path
[2024-02-18 15:59:21,213] 41 root - INFO -Data ingestion completed and artifact: DataIngestionArtifact(trained_file_path='artifact\\02_18_2024_15_58_56\\data_ingestion\\ingested\\train.csv')
[2024-02-18 15:59:21,309] 28 root - INFO -Required number of columns: 5
[2024-02-18 15:59:21,310] 29 root - INFO -Data frame has columns: 5
[2024-02-18 15:59:21,310] 48 root - INFO -Missing numerical columns: [[]]
[2024-02-18 15:59:21,311] 136 root - INFO -Data validation artifact: DataValidationArtifact(validation_status=True, valid_train_file_path='artifact\\02_18_2024_15_58_56\\data_ingestion\\ingested\\train.csv', invalid_train_file_path=None, invalid_test_file_path=None, drift_report_file_path='artifact\\02_18_2024_15_58_56\\data_validation\\drift_report\\report.yaml')
[2024-02-18 15:59:23,063] 48 root - INFO -Entered the save_object method of MainUtils class
[2024-02-18 15:59:23,066] 52 root - INFO -Exited the save_object method of MainUtils class
[2024-02-18 15:59:23,067] 48 root - INFO -Entered the save_object method of MainUtils class
[2024-02-18 15:59:23,070] 52 root - INFO -Exited the save_object method of MainUtils class
[2024-02-18 15:59:23,100] 216 root - INFO -Data transformation artifact: DataTransformationArtifact(transformed_object_file_path='artifact\\02_18_2024_15_58_56\\data_transformation\\transformed_object\\preprocessing.pkl', transformed_object2_file_path='artifact\\02_18_2024_15_58_56\\data_transformation\\transformed_object\\preprocessing1.pkl', transformed_train_file_path='artifact\\02_18_2024_15_58_56\\data_transformation\\transformed\\train.npy', transformed_test_file_path='artifact\\02_18_2024_15_58_56\\data_transformation\\transformed\\test.npy', transformed_train_file_path1='artifact\\02_18_2024_15_58_56\\data_transformation\\transformed_object\\train.csv')
[2024-02-18 15:59:23,359] 48 root - INFO -Entered the save_object method of MainUtils class
[2024-02-18 15:59:23,373] 52 root - INFO -Exited the save_object method of MainUtils class
[2024-02-18 15:59:23,373] 48 root - INFO -Entered the save_object method of MainUtils class
[2024-02-18 15:59:23,387] 52 root - INFO -Exited the save_object method of MainUtils class
[2024-02-18 15:59:23,388] 95 root - INFO -Model trainer artifact: ModelTrainerArtifact(trained_model_file_path='artifact\\02_18_2024_15_58_56\\model_trainer\\trained_model\\model.pkl', train_metric_artifact=regressionMetricArtifact(f1_score=0.8723404255319148, precision_score=0.9111111111111111, recall_score=0.8367346938775511), test_metric_artifact=regressionMetricArtifact(f1_score=0.4761904761904762, precision_score=0.4166666666666667, recall_score=0.5555555555555556))
[2024-02-18 15:59:23,629] 113 root - INFO -Model evaluation artifact: ModelEvaluationArtifact(is_model_accepted=False, improved_accuracy=0.0, best_model_path='saved_models\\1708251255\\model.pkl', trained_model_path='artifact\\02_18_2024_15_58_56\\model_trainer\\trained_model\\model.pkl', train_model_metric_artifact=regressionMetricArtifact(f1_score=0.8723404255319148, precision_score=0.9111111111111111, recall_score=0.8367346938775511), best_model_metric_artifact=regressionMetricArtifact(f1_score=0.8723404255319148, precision_score=0.9111111111111111, recall_score=0.8367346938775511))
[2024-02-18 15:59:23,905] 241 django.request - ERROR -Internal Server Error: /prediction
Traceback (most recent call last):
  File "C:\Users\DELL\PycharmProjects\django\myproject\src\pipeline\training_pipeline.py", line 128, in run_pipeline
    raise Exception("Trained model is not better than the best model")
Exception: Trained model is not better than the best model

During handling of the above exception, another exception occurred:

Traceback (most recent call last):
  File "C:\Users\DELL\Anaconda3\lib\site-packages\django\core\handlers\exception.py", line 55, in inner
    response = get_response(request)
  File "C:\Users\DELL\Anaconda3\lib\site-packages\django\core\handlers\base.py", line 197, in _get_response
    response = wrapped_callback(request, *callback_args, **callback_kwargs)
  File "C:\Users\DELL\PycharmProjects\django\myproject\trade\views.py", line 40, in prediction
    train_pipeline.run_pipeline()
  File "C:\Users\DELL\PycharmProjects\django\myproject\src\pipeline\training_pipeline.py", line 136, in run_pipeline
    raise SensorException(e,sys)
src.exception.SensorException: Error occurred python script name [C:\Users\DELL\PycharmProjects\django\myproject\src\pipeline\training_pipeline.py] line number [128] error message [Trained model is not better than the best model]
