[2024-02-18 15:33:38,148] 160 numexpr.utils - INFO -NumExpr defaulting to 4 threads.
[2024-02-18 15:33:56,019] 241 django.request - ERROR -Internal Server Error: /prediction
Traceback (most recent call last):
  File "C:\Users\DELL\Anaconda3\lib\site-packages\django\core\handlers\exception.py", line 55, in inner
    response = get_response(request)
  File "C:\Users\DELL\Anaconda3\lib\site-packages\django\utils\deprecation.py", line 136, in __call__
    response = self.process_response(request, response)
  File "C:\Users\DELL\Anaconda3\lib\site-packages\django\middleware\common.py", line 108, in process_response
    return self.response_redirect_class(self.get_full_path_with_slash(request))
  File "C:\Users\DELL\Anaconda3\lib\site-packages\django\middleware\common.py", line 87, in get_full_path_with_slash
    raise RuntimeError(
RuntimeError: You called this URL via POST, but the URL doesn't end in a slash and you have APPEND_SLASH set. Django can't redirect to the slash URL while maintaining POST data. Change your form to point to 127.0.0.1:8000/prediction/ (note the trailing slash), or set APPEND_SLASH=False in your Django settings.
[2024-02-18 15:34:02,414] 241 django.request - ERROR -Internal Server Error: /prediction/
Traceback (most recent call last):
  File "C:\Users\DELL\PycharmProjects\django\myproject\src\pipeline\training_pipeline.py", line 120, in run_pipeline
    a.fyersinitiation(self.symbol)
  File "C:\Users\DELL\PycharmProjects\django\myproject\src\components\fyers.py", line 208, in fyersinitiation
    collection = DB[symbol]
  File "C:\Users\DELL\Anaconda3\lib\site-packages\pymongo\database.py", line 237, in __getitem__
    return Collection(self, name)
  File "C:\Users\DELL\Anaconda3\lib\site-packages\pymongo\collection.py", line 208, in __init__
    raise InvalidName("collection names cannot be empty")
pymongo.errors.InvalidName: collection names cannot be empty

During handling of the above exception, another exception occurred:

Traceback (most recent call last):
  File "C:\Users\DELL\Anaconda3\lib\site-packages\django\core\handlers\exception.py", line 55, in inner
    response = get_response(request)
  File "C:\Users\DELL\Anaconda3\lib\site-packages\django\core\handlers\base.py", line 197, in _get_response
    response = wrapped_callback(request, *callback_args, **callback_kwargs)
  File "C:\Users\DELL\PycharmProjects\django\myproject\trade\views.py", line 43, in prediction
    train_pipeline.run_pipeline()
  File "C:\Users\DELL\PycharmProjects\django\myproject\src\pipeline\training_pipeline.py", line 136, in run_pipeline
    raise SensorException(e,sys)
src.exception.SensorException: Error occurred python script name [C:\Users\DELL\PycharmProjects\django\myproject\src\pipeline\training_pipeline.py] line number [120] error message [collection names cannot be empty]
[2024-02-18 15:35:54,109] 266 django.utils.autoreload - INFO -C:\Users\DELL\PycharmProjects\django\myproject\expensewebsite\settings.py changed, reloading.
