[2024-02-18 15:09:04,493] 160 numexpr.utils - INFO -NumExpr defaulting to 4 threads.
[2024-02-18 15:09:20,268] 241 django.request - WARNING -Not Found: /prediction/
[2024-02-18 15:09:25,256] 241 django.request - WARNING -Not Found: /prediction/
[2024-02-18 15:09:30,265] 241 django.request - WARNING -Not Found: /prediction/
[2024-02-18 15:09:35,266] 241 django.request - WARNING -Not Found: /prediction/
[2024-02-18 15:09:39,918] 38 root - INFO -starting data ingestion
[2024-02-18 15:09:40,054] 41 root - INFO -performed train test split on dataframe
[2024-02-18 15:09:40,055] 42 root - INFO -exited split_data as train test split
[2024-02-18 15:09:40,058] 47 root - INFO -exporting train and test file path
[2024-02-18 15:09:40,114] 52 root - INFO -exported train and test file path
[2024-02-18 15:09:40,115] 41 root - INFO -Data ingestion completed and artifact: DataIngestionArtifact(trained_file_path='artifact\\02_18_2024_15_09_03\\data_ingestion\\ingested\\train.csv')
[2024-02-18 15:09:40,241] 28 root - INFO -Required number of columns: 5
[2024-02-18 15:09:40,245] 29 root - INFO -Data frame has columns: 5
[2024-02-18 15:09:40,246] 48 root - INFO -Missing numerical columns: [[]]
[2024-02-18 15:09:40,246] 136 root - INFO -Data validation artifact: DataValidationArtifact(validation_status=True, valid_train_file_path='artifact\\02_18_2024_15_09_03\\data_ingestion\\ingested\\train.csv', invalid_train_file_path=None, invalid_test_file_path=None, drift_report_file_path='artifact\\02_18_2024_15_09_03\\data_validation\\drift_report\\report.yaml')
[2024-02-18 15:09:40,284] 241 django.request - WARNING -Not Found: /prediction/
[2024-02-18 15:09:42,123] 48 root - INFO -Entered the save_object method of MainUtils class
[2024-02-18 15:09:42,127] 52 root - INFO -Exited the save_object method of MainUtils class
[2024-02-18 15:09:42,127] 48 root - INFO -Entered the save_object method of MainUtils class
[2024-02-18 15:09:42,131] 52 root - INFO -Exited the save_object method of MainUtils class
[2024-02-18 15:09:42,176] 216 root - INFO -Data transformation artifact: DataTransformationArtifact(transformed_object_file_path='artifact\\02_18_2024_15_09_03\\data_transformation\\transformed_object\\preprocessing.pkl', transformed_object2_file_path='artifact\\02_18_2024_15_09_03\\data_transformation\\transformed_object\\preprocessing1.pkl', transformed_train_file_path='artifact\\02_18_2024_15_09_03\\data_transformation\\transformed\\train.npy', transformed_test_file_path='artifact\\02_18_2024_15_09_03\\data_transformation\\transformed\\test.npy', transformed_train_file_path1='artifact\\02_18_2024_15_09_03\\data_transformation\\transformed_object\\train.csv')
[2024-02-18 15:09:42,427] 48 root - INFO -Entered the save_object method of MainUtils class
[2024-02-18 15:09:42,444] 52 root - INFO -Exited the save_object method of MainUtils class
[2024-02-18 15:09:42,445] 48 root - INFO -Entered the save_object method of MainUtils class
[2024-02-18 15:09:42,461] 52 root - INFO -Exited the save_object method of MainUtils class
[2024-02-18 15:09:42,462] 95 root - INFO -Model trainer artifact: ModelTrainerArtifact(trained_model_file_path='artifact\\02_18_2024_15_09_03\\model_trainer\\trained_model\\model.pkl', train_metric_artifact=regressionMetricArtifact(f1_score=0.8723404255319148, precision_score=0.9111111111111111, recall_score=0.8367346938775511), test_metric_artifact=regressionMetricArtifact(f1_score=0.4761904761904762, precision_score=0.4166666666666667, recall_score=0.5555555555555556))
[2024-02-18 15:09:42,694] 113 root - INFO -Model evaluation artifact: ModelEvaluationArtifact(is_model_accepted=False, improved_accuracy=0.0, best_model_path='saved_models\\1708247726\\model.pkl', trained_model_path='artifact\\02_18_2024_15_09_03\\model_trainer\\trained_model\\model.pkl', train_model_metric_artifact=regressionMetricArtifact(f1_score=0.8723404255319148, precision_score=0.9111111111111111, recall_score=0.8367346938775511), best_model_metric_artifact=regressionMetricArtifact(f1_score=0.8723404255319148, precision_score=0.9111111111111111, recall_score=0.8367346938775511))
[2024-02-18 15:09:43,032] 241 django.request - ERROR -Internal Server Error: /prediction
Traceback (most recent call last):
  File "C:\Users\DELL\PycharmProjects\django\myproject\src\pipeline\training_pipeline.py", line 128, in run_pipeline
    raise Exception("Trained model is not better than the best model")
Exception: Trained model is not better than the best model

During handling of the above exception, another exception occurred:

Traceback (most recent call last):
  File "C:\Users\DELL\Anaconda3\lib\site-packages\django\core\handlers\exception.py", line 55, in inner
    response = get_response(request)
  File "C:\Users\DELL\Anaconda3\lib\site-packages\django\core\handlers\base.py", line 197, in _get_response
    response = wrapped_callback(request, *callback_args, **callback_kwargs)
  File "C:\Users\DELL\PycharmProjects\django\myproject\trade\views.py", line 43, in prediction
    train_pipeline.run_pipeline()
  File "C:\Users\DELL\PycharmProjects\django\myproject\src\pipeline\training_pipeline.py", line 136, in run_pipeline
    raise SensorException(e,sys)
src.exception.SensorException: Error occurred python script name [C:\Users\DELL\PycharmProjects\django\myproject\src\pipeline\training_pipeline.py] line number [128] error message [Trained model is not better than the best model]
[2024-02-18 15:10:23,958] 241 django.request - WARNING -Not Found: /prediction/
[2024-02-18 15:10:28,951] 241 django.request - WARNING -Not Found: /prediction/
[2024-02-18 15:10:33,947] 241 django.request - WARNING -Not Found: /prediction/
[2024-02-18 15:10:44,777] 241 django.request - WARNING -Not Found: /prediction/
[2024-02-18 15:10:49,778] 241 django.request - WARNING -Not Found: /prediction/
[2024-02-18 15:10:54,767] 241 django.request - WARNING -Not Found: /prediction/
[2024-02-18 15:10:59,776] 241 django.request - WARNING -Not Found: /prediction/
[2024-02-18 15:11:04,938] 241 django.request - WARNING -Not Found: /prediction/
[2024-02-18 15:11:09,777] 241 django.request - WARNING -Not Found: /prediction/
[2024-02-18 15:11:14,770] 241 django.request - WARNING -Not Found: /prediction/
[2024-02-18 15:11:19,773] 241 django.request - WARNING -Not Found: /prediction/
[2024-02-18 15:11:24,771] 241 django.request - WARNING -Not Found: /prediction/
[2024-02-18 15:11:29,767] 241 django.request - WARNING -Not Found: /prediction/
[2024-02-18 15:11:34,774] 241 django.request - WARNING -Not Found: /prediction/
[2024-02-18 15:11:39,774] 241 django.request - WARNING -Not Found: /prediction/
[2024-02-18 15:11:41,806] 38 root - INFO -starting data ingestion
[2024-02-18 15:11:41,926] 41 root - INFO -performed train test split on dataframe
[2024-02-18 15:11:41,926] 42 root - INFO -exited split_data as train test split
[2024-02-18 15:11:41,927] 47 root - INFO -exporting train and test file path
[2024-02-18 15:11:42,015] 52 root - INFO -exported train and test file path
[2024-02-18 15:11:42,016] 41 root - INFO -Data ingestion completed and artifact: DataIngestionArtifact(trained_file_path='artifact\\02_18_2024_15_09_03\\data_ingestion\\ingested\\train.csv')
[2024-02-18 15:11:42,216] 28 root - INFO -Required number of columns: 5
[2024-02-18 15:11:42,216] 29 root - INFO -Data frame has columns: 5
[2024-02-18 15:11:42,216] 48 root - INFO -Missing numerical columns: [[]]
[2024-02-18 15:11:42,217] 136 root - INFO -Data validation artifact: DataValidationArtifact(validation_status=True, valid_train_file_path='artifact\\02_18_2024_15_09_03\\data_ingestion\\ingested\\train.csv', invalid_train_file_path=None, invalid_test_file_path=None, drift_report_file_path='artifact\\02_18_2024_15_09_03\\data_validation\\drift_report\\report.yaml')
[2024-02-18 15:11:44,066] 48 root - INFO -Entered the save_object method of MainUtils class
[2024-02-18 15:11:44,069] 52 root - INFO -Exited the save_object method of MainUtils class
[2024-02-18 15:11:44,069] 48 root - INFO -Entered the save_object method of MainUtils class
[2024-02-18 15:11:44,071] 52 root - INFO -Exited the save_object method of MainUtils class
[2024-02-18 15:11:44,102] 216 root - INFO -Data transformation artifact: DataTransformationArtifact(transformed_object_file_path='artifact\\02_18_2024_15_09_03\\data_transformation\\transformed_object\\preprocessing.pkl', transformed_object2_file_path='artifact\\02_18_2024_15_09_03\\data_transformation\\transformed_object\\preprocessing1.pkl', transformed_train_file_path='artifact\\02_18_2024_15_09_03\\data_transformation\\transformed\\train.npy', transformed_test_file_path='artifact\\02_18_2024_15_09_03\\data_transformation\\transformed\\test.npy', transformed_train_file_path1='artifact\\02_18_2024_15_09_03\\data_transformation\\transformed_object\\train.csv')
[2024-02-18 15:11:44,261] 48 root - INFO -Entered the save_object method of MainUtils class
[2024-02-18 15:11:44,273] 52 root - INFO -Exited the save_object method of MainUtils class
[2024-02-18 15:11:44,273] 48 root - INFO -Entered the save_object method of MainUtils class
[2024-02-18 15:11:44,286] 52 root - INFO -Exited the save_object method of MainUtils class
[2024-02-18 15:11:44,286] 95 root - INFO -Model trainer artifact: ModelTrainerArtifact(trained_model_file_path='artifact\\02_18_2024_15_09_03\\model_trainer\\trained_model\\model.pkl', train_metric_artifact=regressionMetricArtifact(f1_score=0.8723404255319148, precision_score=0.9111111111111111, recall_score=0.8367346938775511), test_metric_artifact=regressionMetricArtifact(f1_score=0.4761904761904762, precision_score=0.4166666666666667, recall_score=0.5555555555555556))
[2024-02-18 15:11:44,319] 75 root - INFO -Model evaluation artifact: ModelEvaluationArtifact(is_model_accepted=True, improved_accuracy=None, best_model_path=None, trained_model_path='artifact\\02_18_2024_15_09_03\\model_trainer\\trained_model\\model.pkl', train_model_metric_artifact=regressionMetricArtifact(f1_score=0.4761904761904762, precision_score=0.4166666666666667, recall_score=0.5555555555555556), best_model_metric_artifact=None)
[2024-02-18 15:11:44,744] 241 django.request - ERROR -Internal Server Error: /prediction
Traceback (most recent call last):
  File "C:\Users\DELL\Anaconda3\lib\site-packages\django\core\handlers\exception.py", line 55, in inner
    response = get_response(request)
  File "C:\Users\DELL\Anaconda3\lib\site-packages\django\core\handlers\base.py", line 197, in _get_response
    response = wrapped_callback(request, *callback_args, **callback_kwargs)
  File "C:\Users\DELL\PycharmProjects\django\myproject\trade\views.py", line 44, in prediction
    progress = train_pipeline.run_pipeline(progress_callback=update_progress)
TypeError: TrainPipeline.run_pipeline() got an unexpected keyword argument 'progress_callback'
[2024-02-18 15:17:59,141] 266 django.utils.autoreload - INFO -C:\Users\DELL\PycharmProjects\django\myproject\src\pipeline\training_pipeline.py changed, reloading.
