[2024-02-26 13:03:26,132] 160 numexpr.utils - INFO -NumExpr defaulting to 4 threads.
[2024-02-26 13:10:16,338] 241 django.request - WARNING -Not Found: /docs/5.3/dist/js/bootstrap.bundle.min.js
[2024-02-26 13:10:16,342] 241 django.request - WARNING -Not Found: /docs/5.3/assets/js/color-modes.js
[2024-02-26 13:51:34,547] 241 django.request - WARNING -Not Found: /docs/5.3/assets/js/color-modes.js
[2024-02-26 13:51:34,567] 241 django.request - WARNING -Not Found: /docs/5.3/dist/js/bootstrap.bundle.min.js
[2024-02-26 13:51:36,558] 241 django.request - WARNING -Conflict: /authentication/validate-username
[2024-02-26 13:51:53,514] 241 django.request - WARNING -Conflict: /authentication/validate-email
[2024-02-26 13:51:58,689] 241 django.request - WARNING -Bad Request: /authentication/validate-email
[2024-02-26 13:52:13,988] 241 django.request - ERROR -Internal Server Error: /authentication/register
Traceback (most recent call last):
  File "C:\Users\DELL\Anaconda3\lib\site-packages\django\core\handlers\exception.py", line 55, in inner
    response = get_response(request)
  File "C:\Users\DELL\Anaconda3\lib\site-packages\django\core\handlers\base.py", line 197, in _get_response
    response = wrapped_callback(request, *callback_args, **callback_kwargs)
  File "C:\Users\DELL\Anaconda3\lib\site-packages\django\views\generic\base.py", line 104, in view
    return self.dispatch(request, *args, **kwargs)
  File "C:\Users\DELL\Anaconda3\lib\site-packages\django\views\generic\base.py", line 143, in dispatch
    return handler(request, *args, **kwargs)
  File "C:\Users\DELL\PycharmProjects\django\myproject\authentication\views.py", line 88, in post
    email.send(fail_silently=False)
  File "C:\Users\DELL\Anaconda3\lib\site-packages\django\core\mail\message.py", line 300, in send
    return self.get_connection(fail_silently).send_messages([self])
  File "C:\Users\DELL\Anaconda3\lib\site-packages\django\core\mail\backends\smtp.py", line 128, in send_messages
    new_conn_created = self.open()
  File "C:\Users\DELL\Anaconda3\lib\site-packages\django\core\mail\backends\smtp.py", line 86, in open
    self.connection = self.connection_class(
  File "C:\Users\DELL\Anaconda3\lib\smtplib.py", line 255, in __init__
    (code, msg) = self.connect(host, port)
  File "C:\Users\DELL\Anaconda3\lib\smtplib.py", line 341, in connect
    self.sock = self._get_socket(host, port, self.timeout)
  File "C:\Users\DELL\Anaconda3\lib\smtplib.py", line 312, in _get_socket
    return socket.create_connection((host, port), timeout,
  File "C:\Users\DELL\Anaconda3\lib\socket.py", line 824, in create_connection
    for res in getaddrinfo(host, port, 0, SOCK_STREAM):
  File "C:\Users\DELL\Anaconda3\lib\socket.py", line 955, in getaddrinfo
    for res in _socket.getaddrinfo(host, port, family, type, proto, flags):
socket.gaierror: [Errno 11003] getaddrinfo failed
[2024-02-26 13:52:36,961] 241 django.request - WARNING -Conflict: /authentication/validate-email
[2024-02-26 13:52:41,382] 241 django.request - WARNING -Conflict: /authentication/validate-email
[2024-02-26 13:52:58,781] 241 django.request - WARNING -Not Found: /docs/5.3/assets/js/color-modes.js
[2024-02-26 13:52:58,828] 241 django.request - WARNING -Not Found: /docs/5.3/dist/js/bootstrap.bundle.min.js
[2024-02-26 13:53:07,170] 241 django.request - WARNING -Not Found: /docs/5.3/assets/js/color-modes.js
[2024-02-26 13:53:16,962] 241 django.request - WARNING -Not Found: /docs/5.3/assets/js/color-modes.js
[2024-02-26 13:53:17,020] 241 django.request - WARNING -Not Found: /docs/5.3/dist/js/bootstrap.bundle.min.js
[2024-02-26 13:53:30,804] 241 django.request - WARNING -Not Found: /docs/5.3/assets/js/color-modes.js
[2024-02-26 13:53:30,839] 241 django.request - WARNING -Not Found: /docs/5.3/dist/js/bootstrap.bundle.min.js
[2024-02-26 13:53:44,204] 241 django.request - WARNING -Not Found: /docs/5.3/assets/js/color-modes.js
[2024-02-26 13:53:44,268] 241 django.request - WARNING -Not Found: /docs/5.3/dist/js/bootstrap.bundle.min.js
[2024-02-26 13:54:03,199] 241 django.request - WARNING -Not Found: /docs/5.3/assets/js/color-modes.js
[2024-02-26 13:54:03,234] 241 django.request - WARNING -Not Found: /docs/5.3/dist/js/bootstrap.bundle.min.js
[2024-02-26 13:55:23,720] 241 django.request - WARNING -Not Found: /docs/5.3/assets/js/color-modes.js
[2024-02-26 13:55:30,860] 241 django.request - WARNING -Not Found: /docs/5.3/assets/js/color-modes.js
[2024-02-26 13:55:30,924] 241 django.request - WARNING -Not Found: /docs/5.3/dist/js/bootstrap.bundle.min.js
[2024-02-26 13:55:32,124] 241 django.request - WARNING -Conflict: /authentication/validate-username
[2024-02-26 13:55:38,849] 241 django.request - WARNING -Conflict: /authentication/validate-username
[2024-02-26 13:56:04,652] 241 django.request - ERROR -Internal Server Error: /authentication/register
Traceback (most recent call last):
  File "C:\Users\DELL\Anaconda3\lib\site-packages\django\core\handlers\exception.py", line 55, in inner
    response = get_response(request)
  File "C:\Users\DELL\Anaconda3\lib\site-packages\django\core\handlers\base.py", line 197, in _get_response
    response = wrapped_callback(request, *callback_args, **callback_kwargs)
  File "C:\Users\DELL\Anaconda3\lib\site-packages\django\views\generic\base.py", line 104, in view
    return self.dispatch(request, *args, **kwargs)
  File "C:\Users\DELL\Anaconda3\lib\site-packages\django\views\generic\base.py", line 143, in dispatch
    return handler(request, *args, **kwargs)
  File "C:\Users\DELL\PycharmProjects\django\myproject\authentication\views.py", line 88, in post
    email.send(fail_silently=False)
  File "C:\Users\DELL\Anaconda3\lib\site-packages\django\core\mail\message.py", line 300, in send
    return self.get_connection(fail_silently).send_messages([self])
  File "C:\Users\DELL\Anaconda3\lib\site-packages\django\core\mail\backends\smtp.py", line 128, in send_messages
    new_conn_created = self.open()
  File "C:\Users\DELL\Anaconda3\lib\site-packages\django\core\mail\backends\smtp.py", line 86, in open
    self.connection = self.connection_class(
  File "C:\Users\DELL\Anaconda3\lib\smtplib.py", line 255, in __init__
    (code, msg) = self.connect(host, port)
  File "C:\Users\DELL\Anaconda3\lib\smtplib.py", line 341, in connect
    self.sock = self._get_socket(host, port, self.timeout)
  File "C:\Users\DELL\Anaconda3\lib\smtplib.py", line 312, in _get_socket
    return socket.create_connection((host, port), timeout,
  File "C:\Users\DELL\Anaconda3\lib\socket.py", line 824, in create_connection
    for res in getaddrinfo(host, port, 0, SOCK_STREAM):
  File "C:\Users\DELL\Anaconda3\lib\socket.py", line 955, in getaddrinfo
    for res in _socket.getaddrinfo(host, port, family, type, proto, flags):
socket.gaierror: [Errno 11003] getaddrinfo failed
[2024-02-26 13:56:18,377] 241 django.request - WARNING -Bad Request: /authentication/validate-email
[2024-02-26 13:56:33,095] 241 django.request - WARNING -Bad Request: /authentication/validate-email
[2024-02-26 13:56:33,751] 241 django.request - WARNING -Bad Request: /authentication/validate-email
[2024-02-26 13:56:37,046] 241 django.request - WARNING -Bad Request: /authentication/validate-email
[2024-02-26 13:56:38,541] 241 django.request - WARNING -Bad Request: /authentication/validate-email
[2024-02-26 13:56:38,758] 241 django.request - WARNING -Bad Request: /authentication/validate-email
[2024-02-26 13:56:39,238] 241 django.request - WARNING -Bad Request: /authentication/validate-email
[2024-02-26 13:56:39,623] 241 django.request - WARNING -Bad Request: /authentication/validate-email
[2024-02-26 13:56:40,062] 241 django.request - WARNING -Bad Request: /authentication/validate-email
[2024-02-26 13:56:42,041] 241 django.request - WARNING -Conflict: /authentication/validate-email
[2024-02-26 13:56:42,285] 241 django.request - WARNING -Conflict: /authentication/validate-email
[2024-02-26 13:56:55,183] 241 django.request - WARNING -Not Found: /docs/5.3/assets/js/color-modes.js
[2024-02-26 13:56:55,225] 241 django.request - WARNING -Not Found: /docs/5.3/dist/js/bootstrap.bundle.min.js
[2024-02-26 14:13:42,943] 241 django.request - WARNING -Not Found: /docs/5.3/assets/js/color-modes.js
[2024-02-26 14:13:49,220] 241 django.request - ERROR -Internal Server Error: /authentication/login
Traceback (most recent call last):
  File "C:\Users\DELL\Anaconda3\lib\site-packages\django\core\handlers\exception.py", line 55, in inner
    response = get_response(request)
  File "C:\Users\DELL\Anaconda3\lib\site-packages\django\core\handlers\base.py", line 197, in _get_response
    response = wrapped_callback(request, *callback_args, **callback_kwargs)
  File "C:\Users\DELL\Anaconda3\lib\site-packages\django\views\generic\base.py", line 104, in view
    return self.dispatch(request, *args, **kwargs)
  File "C:\Users\DELL\Anaconda3\lib\site-packages\django\views\generic\base.py", line 143, in dispatch
    return handler(request, *args, **kwargs)
  File "C:\Users\DELL\PycharmProjects\django\myproject\authentication\views.py", line 134, in post
    return redirect('expenses')
  File "C:\Users\DELL\Anaconda3\lib\site-packages\django\shortcuts.py", line 49, in redirect
    return redirect_class(resolve_url(to, *args, **kwargs))
  File "C:\Users\DELL\Anaconda3\lib\site-packages\django\shortcuts.py", line 180, in resolve_url
    return reverse(to, args=args, kwargs=kwargs)
  File "C:\Users\DELL\Anaconda3\lib\site-packages\django\urls\base.py", line 88, in reverse
    return resolver._reverse_with_prefix(view, prefix, *args, **kwargs)
  File "C:\Users\DELL\Anaconda3\lib\site-packages\django\urls\resolvers.py", line 851, in _reverse_with_prefix
    raise NoReverseMatch(msg)
django.urls.exceptions.NoReverseMatch: Reverse for 'expenses' not found. 'expenses' is not a valid view function or pattern name.
[2024-02-26 14:18:33,044] 266 django.utils.autoreload - INFO -C:\Users\DELL\PycharmProjects\django\myproject\authentication\views.py changed, reloading.
