[2024-02-29 16:08:54,067] 230 django.request - ERROR -Internal Server Error: /authentication/login
Traceback (most recent call last):
  File "C:\Users\DELL\anaconda3\envs\dai5\lib\site-packages\django\utils\datastructures.py", line 76, in __getitem__
    list_ = super().__getitem__(key)
KeyError: 'password'

During handling of the above exception, another exception occurred:

Traceback (most recent call last):
  File "C:\Users\DELL\anaconda3\envs\dai5\lib\site-packages\django\core\handlers\exception.py", line 47, in inner
    response = get_response(request)
  File "C:\Users\DELL\anaconda3\envs\dai5\lib\site-packages\django\core\handlers\base.py", line 181, in _get_response
    response = wrapped_callback(request, *callback_args, **callback_kwargs)
  File "C:\Users\DELL\anaconda3\envs\dai5\lib\site-packages\django\views\generic\base.py", line 70, in view
    return self.dispatch(request, *args, **kwargs)
  File "C:\Users\DELL\anaconda3\envs\dai5\lib\site-packages\django\views\generic\base.py", line 98, in dispatch
    return handler(request, *args, **kwargs)
  File "C:\Users\DELL\PycharmProjects\django\myproject\authentication\views.py", line 109, in post
    password = request.POST['password']
  File "C:\Users\DELL\anaconda3\envs\dai5\lib\site-packages\django\utils\datastructures.py", line 78, in __getitem__
    raise MultiValueDictKeyError(key)
django.utils.datastructures.MultiValueDictKeyError: 'password'
[2024-02-29 16:10:40,949] 251 django.utils.autoreload - INFO -C:\Users\DELL\PycharmProjects\django\myproject\trade\views.py changed, reloading.
