[2024-02-26 21:19:53,202] 160 numexpr.utils - INFO -NumExpr defaulting to 4 threads.
[2024-02-26 21:20:13,543] 241 django.request - WARNING -Not Found: /docs/5.3/assets/js/color-modes.js
[2024-02-26 21:20:15,396] 241 django.request - WARNING -Conflict: /authentication/validate-username
[2024-02-26 21:20:34,556] 241 django.request - WARNING -Bad Request: /authentication/validate-email
[2024-02-26 21:20:36,564] 241 django.request - WARNING -Bad Request: /authentication/validate-email
[2024-02-26 21:20:36,989] 241 django.request - WARNING -Bad Request: /authentication/validate-email
[2024-02-26 21:20:37,501] 241 django.request - WARNING -Bad Request: /authentication/validate-email
[2024-02-26 21:20:37,821] 241 django.request - WARNING -Bad Request: /authentication/validate-email
[2024-02-26 21:20:38,173] 241 django.request - WARNING -Bad Request: /authentication/validate-email
[2024-02-26 21:20:38,485] 241 django.request - WARNING -Bad Request: /authentication/validate-email
[2024-02-26 21:20:38,821] 241 django.request - WARNING -Bad Request: /authentication/validate-email
[2024-02-26 21:20:39,181] 241 django.request - WARNING -Bad Request: /authentication/validate-email
[2024-02-26 21:20:39,557] 241 django.request - WARNING -Bad Request: /authentication/validate-email
[2024-02-26 21:20:39,861] 241 django.request - WARNING -Bad Request: /authentication/validate-email
[2024-02-26 21:20:40,372] 241 django.request - WARNING -Bad Request: /authentication/validate-email
[2024-02-26 21:20:40,660] 241 django.request - WARNING -Bad Request: /authentication/validate-email
[2024-02-26 21:20:41,101] 241 django.request - WARNING -Bad Request: /authentication/validate-email
[2024-02-26 21:20:41,436] 241 django.request - WARNING -Bad Request: /authentication/validate-email
[2024-02-26 21:20:42,582] 241 django.request - WARNING -Bad Request: /authentication/validate-email
[2024-02-26 21:20:42,619] 241 django.request - WARNING -Bad Request: /authentication/validate-email
[2024-02-26 21:20:45,596] 241 django.request - WARNING -Bad Request: /authentication/validate-email
[2024-02-26 21:21:06,662] 241 django.request - ERROR -Internal Server Error: /authentication/register
Traceback (most recent call last):
  File "C:\Users\DELL\Anaconda3\lib\site-packages\django\core\handlers\exception.py", line 55, in inner
    response = get_response(request)
  File "C:\Users\DELL\Anaconda3\lib\site-packages\django\core\handlers\base.py", line 197, in _get_response
    response = wrapped_callback(request, *callback_args, **callback_kwargs)
  File "C:\Users\DELL\Anaconda3\lib\site-packages\django\views\generic\base.py", line 104, in view
    return self.dispatch(request, *args, **kwargs)
  File "C:\Users\DELL\Anaconda3\lib\site-packages\django\views\generic\base.py", line 143, in dispatch
    return handler(request, *args, **kwargs)
  File "C:\Users\DELL\PycharmProjects\django\myproject\authentication\views.py", line 75, in post
    server.login(sender_email,password)
  File "C:\Users\DELL\Anaconda3\lib\smtplib.py", line 750, in login
    raise last_exception
  File "C:\Users\DELL\Anaconda3\lib\smtplib.py", line 739, in login
    (code, resp) = self.auth(
  File "C:\Users\DELL\Anaconda3\lib\smtplib.py", line 662, in auth
    raise SMTPAuthenticationError(code, resp)
smtplib.SMTPAuthenticationError: (535, b'5.7.8 Username and Password not accepted. For more information, go to\n5.7.8  https://support.google.com/mail/?p=BadCredentials sb13-20020a17090b50cd00b0029a8d207010sm5624538pjb.54 - gsmtp')
[2024-02-26 21:22:00,643] 266 django.utils.autoreload - INFO -C:\Users\DELL\PycharmProjects\django\myproject\authentication\views.py changed, reloading.
