[2024-02-26 18:05:12,180] 160 numexpr.utils - INFO -NumExpr defaulting to 4 threads.
[2024-02-26 18:05:45,950] 241 django.request - WARNING -Not Found: /docs/5.3/assets/js/color-modes.js
[2024-02-26 18:05:50,560] 241 django.request - WARNING -Not Found: /docs/5.3/assets/js/color-modes.js
[2024-02-26 18:05:51,911] 241 django.request - WARNING -Conflict: /authentication/validate-username
[2024-02-26 18:06:39,901] 241 django.request - WARNING -Bad Request: /authentication/validate-email
[2024-02-26 18:06:40,429] 241 django.request - WARNING -Bad Request: /authentication/validate-email
[2024-02-26 18:06:40,918] 241 django.request - WARNING -Bad Request: /authentication/validate-email
[2024-02-26 18:06:41,389] 241 django.request - WARNING -Bad Request: /authentication/validate-email
[2024-02-26 18:06:42,154] 241 django.request - WARNING -Bad Request: /authentication/validate-email
[2024-02-26 18:06:42,781] 241 django.request - WARNING -Bad Request: /authentication/validate-email
[2024-02-26 18:06:43,318] 241 django.request - WARNING -Bad Request: /authentication/validate-email
[2024-02-26 18:06:43,661] 241 django.request - WARNING -Bad Request: /authentication/validate-email
[2024-02-26 18:06:44,333] 241 django.request - WARNING -Bad Request: /authentication/validate-email
[2024-02-26 18:06:44,798] 241 django.request - WARNING -Bad Request: /authentication/validate-email
[2024-02-26 18:06:45,381] 241 django.request - WARNING -Bad Request: /authentication/validate-email
[2024-02-26 18:06:47,550] 241 django.request - WARNING -Bad Request: /authentication/validate-email
[2024-02-26 18:06:47,645] 241 django.request - WARNING -Bad Request: /authentication/validate-email
[2024-02-26 18:06:51,464] 241 django.request - WARNING -Conflict: /authentication/validate-email
[2024-02-26 18:06:51,648] 241 django.request - WARNING -Conflict: /authentication/validate-email
[2024-02-26 18:07:54,741] 241 django.request - WARNING -Bad Request: /authentication/validate-email
[2024-02-26 18:07:55,476] 241 django.request - WARNING -Bad Request: /authentication/validate-email
[2024-02-26 18:07:56,612] 241 django.request - WARNING -Bad Request: /authentication/validate-email
[2024-02-26 18:07:57,021] 241 django.request - WARNING -Bad Request: /authentication/validate-email
[2024-02-26 18:07:57,637] 241 django.request - WARNING -Bad Request: /authentication/validate-email
[2024-02-26 18:07:59,525] 241 django.request - WARNING -Bad Request: /authentication/validate-email
[2024-02-26 18:07:59,846] 241 django.request - WARNING -Bad Request: /authentication/validate-email
[2024-02-26 18:08:00,349] 241 django.request - WARNING -Bad Request: /authentication/validate-email
[2024-02-26 18:08:00,740] 241 django.request - WARNING -Bad Request: /authentication/validate-email
[2024-02-26 18:08:01,661] 241 django.request - WARNING -Bad Request: /authentication/validate-email
[2024-02-26 18:08:03,107] 241 django.request - WARNING -Bad Request: /authentication/validate-email
[2024-02-26 18:08:03,725] 241 django.request - WARNING -Bad Request: /authentication/validate-email
[2024-02-26 18:08:04,261] 241 django.request - WARNING -Bad Request: /authentication/validate-email
[2024-02-26 18:08:04,852] 241 django.request - WARNING -Bad Request: /authentication/validate-email
[2024-02-26 18:08:05,670] 241 django.request - WARNING -Bad Request: /authentication/validate-email
[2024-02-26 18:08:07,998] 241 django.request - WARNING -Bad Request: /authentication/validate-email
[2024-02-26 18:08:09,117] 241 django.request - WARNING -Bad Request: /authentication/validate-email
[2024-02-26 18:08:09,164] 241 django.request - WARNING -Bad Request: /authentication/validate-email
[2024-02-26 18:08:12,828] 241 django.request - WARNING -Bad Request: /authentication/validate-email
[2024-02-26 18:08:22,940] 241 django.request - ERROR -Internal Server Error: /authentication/register
Traceback (most recent call last):
  File "C:\Users\DELL\Anaconda3\lib\site-packages\django\core\handlers\exception.py", line 55, in inner
    response = get_response(request)
  File "C:\Users\DELL\Anaconda3\lib\site-packages\django\core\handlers\base.py", line 197, in _get_response
    response = wrapped_callback(request, *callback_args, **callback_kwargs)
  File "C:\Users\DELL\Anaconda3\lib\site-packages\django\views\generic\base.py", line 104, in view
    return self.dispatch(request, *args, **kwargs)
  File "C:\Users\DELL\Anaconda3\lib\site-packages\django\views\generic\base.py", line 143, in dispatch
    return handler(request, *args, **kwargs)
  File "C:\Users\DELL\PycharmProjects\django\myproject\authentication\views.py", line 87, in post
    email.send(fail_silently=False)
  File "C:\Users\DELL\Anaconda3\lib\site-packages\django\core\mail\message.py", line 300, in send
    return self.get_connection(fail_silently).send_messages([self])
  File "C:\Users\DELL\Anaconda3\lib\site-packages\django\core\mail\backends\smtp.py", line 128, in send_messages
    new_conn_created = self.open()
  File "C:\Users\DELL\Anaconda3\lib\site-packages\django\core\mail\backends\smtp.py", line 86, in open
    self.connection = self.connection_class(
  File "C:\Users\DELL\Anaconda3\lib\smtplib.py", line 255, in __init__
    (code, msg) = self.connect(host, port)
  File "C:\Users\DELL\Anaconda3\lib\smtplib.py", line 341, in connect
    self.sock = self._get_socket(host, port, self.timeout)
  File "C:\Users\DELL\Anaconda3\lib\smtplib.py", line 312, in _get_socket
    return socket.create_connection((host, port), timeout,
  File "C:\Users\DELL\Anaconda3\lib\socket.py", line 824, in create_connection
    for res in getaddrinfo(host, port, 0, SOCK_STREAM):
  File "C:\Users\DELL\Anaconda3\lib\socket.py", line 955, in getaddrinfo
    for res in _socket.getaddrinfo(host, port, family, type, proto, flags):
socket.gaierror: [Errno 11003] getaddrinfo failed
[2024-02-26 18:14:34,699] 266 django.utils.autoreload - INFO -C:\Users\DELL\PycharmProjects\django\myproject\authentication\views.py changed, reloading.
