[2024-02-26 21:23:06,479] 160 numexpr.utils - INFO -NumExpr defaulting to 4 threads.
[2024-02-26 21:23:14,725] 241 django.request - WARNING -Not Found: /docs/5.3/assets/js/color-modes.js
[2024-02-26 21:23:16,083] 241 django.request - WARNING -Conflict: /authentication/validate-username
[2024-02-26 21:23:23,966] 241 django.request - WARNING -Bad Request: /authentication/validate-email
[2024-02-26 21:23:26,317] 241 django.request - WARNING -Bad Request: /authentication/validate-email
[2024-02-26 21:23:26,941] 241 django.request - WARNING -Bad Request: /authentication/validate-email
[2024-02-26 21:23:27,357] 241 django.request - WARNING -Bad Request: /authentication/validate-email
[2024-02-26 21:23:29,138] 241 django.request - WARNING -Bad Request: /authentication/validate-email
[2024-02-26 21:23:29,154] 241 django.request - WARNING -Bad Request: /authentication/validate-email
[2024-02-26 21:23:34,069] 241 django.request - WARNING -Bad Request: /authentication/validate-email
[2024-02-26 21:23:34,102] 241 django.request - WARNING -Bad Request: /authentication/validate-email
[2024-02-26 21:23:34,507] 241 django.request - WARNING -Bad Request: /authentication/validate-email
[2024-02-26 21:23:35,148] 241 django.request - WARNING -Bad Request: /authentication/validate-email
[2024-02-26 21:23:35,523] 241 django.request - WARNING -Bad Request: /authentication/validate-email
[2024-02-26 21:23:35,804] 241 django.request - WARNING -Bad Request: /authentication/validate-email
[2024-02-26 21:23:36,139] 241 django.request - WARNING -Bad Request: /authentication/validate-email
[2024-02-26 21:23:36,971] 241 django.request - WARNING -Bad Request: /authentication/validate-email
[2024-02-26 21:23:37,388] 241 django.request - WARNING -Bad Request: /authentication/validate-email
[2024-02-26 21:23:37,852] 241 django.request - WARNING -Bad Request: /authentication/validate-email
[2024-02-26 21:23:38,251] 241 django.request - WARNING -Bad Request: /authentication/validate-email
[2024-02-26 21:23:43,930] 241 django.request - WARNING -Bad Request: /authentication/validate-email
[2024-02-26 21:23:46,127] 241 django.request - WARNING -Bad Request: /authentication/validate-email
[2024-02-26 21:24:15,163] 241 django.request - ERROR -Internal Server Error: /authentication/register
Traceback (most recent call last):
  File "C:\Users\DELL\Anaconda3\lib\site-packages\django\core\handlers\exception.py", line 55, in inner
    response = get_response(request)
  File "C:\Users\DELL\Anaconda3\lib\site-packages\django\core\handlers\base.py", line 197, in _get_response
    response = wrapped_callback(request, *callback_args, **callback_kwargs)
  File "C:\Users\DELL\Anaconda3\lib\site-packages\django\views\generic\base.py", line 104, in view
    return self.dispatch(request, *args, **kwargs)
  File "C:\Users\DELL\Anaconda3\lib\site-packages\django\views\generic\base.py", line 143, in dispatch
    return handler(request, *args, **kwargs)
  File "C:\Users\DELL\PycharmProjects\django\myproject\authentication\views.py", line 97, in post
    email.send()
  File "C:\Users\DELL\Anaconda3\lib\site-packages\django\core\mail\message.py", line 300, in send
    return self.get_connection(fail_silently).send_messages([self])
  File "C:\Users\DELL\Anaconda3\lib\site-packages\django\core\mail\backends\smtp.py", line 128, in send_messages
    new_conn_created = self.open()
  File "C:\Users\DELL\Anaconda3\lib\site-packages\django\core\mail\backends\smtp.py", line 95, in open
    self.connection.login(self.username, self.password)
  File "C:\Users\DELL\Anaconda3\lib\smtplib.py", line 750, in login
    raise last_exception
  File "C:\Users\DELL\Anaconda3\lib\smtplib.py", line 739, in login
    (code, resp) = self.auth(
  File "C:\Users\DELL\Anaconda3\lib\smtplib.py", line 662, in auth
    raise SMTPAuthenticationError(code, resp)
smtplib.SMTPAuthenticationError: (535, b'5.7.8 Username and Password not accepted. For more information, go to\n5.7.8  https://support.google.com/mail/?p=BadCredentials y15-20020a056a00190f00b006e3b868b8b8sm4197213pfi.130 - gsmtp')
[2024-02-26 21:30:33,942] 266 django.utils.autoreload - INFO -C:\Users\DELL\PycharmProjects\django\myproject\authentication\views.py changed, reloading.
