[2024-02-26 21:00:00,529] 160 numexpr.utils - INFO -NumExpr defaulting to 4 threads.
[2024-02-26 21:00:25,881] 241 django.request - WARNING -Not Found: /docs/5.3/assets/js/color-modes.js
[2024-02-26 21:00:30,289] 241 django.request - WARNING -Bad Request: /authentication/validate-email
[2024-02-26 21:00:32,409] 241 django.request - WARNING -Bad Request: /authentication/validate-email
[2024-02-26 21:00:33,000] 241 django.request - WARNING -Bad Request: /authentication/validate-email
[2024-02-26 21:00:33,600] 241 django.request - WARNING -Bad Request: /authentication/validate-email
[2024-02-26 21:00:34,280] 241 django.request - WARNING -Bad Request: /authentication/validate-email
[2024-02-26 21:00:34,640] 241 django.request - WARNING -Bad Request: /authentication/validate-email
[2024-02-26 21:00:35,322] 241 django.request - WARNING -Bad Request: /authentication/validate-email
[2024-02-26 21:00:35,892] 241 django.request - WARNING -Bad Request: /authentication/validate-email
[2024-02-26 21:00:36,577] 241 django.request - WARNING -Bad Request: /authentication/validate-email
[2024-02-26 21:00:39,889] 241 django.request - WARNING -Bad Request: /authentication/validate-email
[2024-02-26 21:00:39,927] 241 django.request - WARNING -Bad Request: /authentication/validate-email
[2024-02-26 21:00:43,159] 241 django.request - WARNING -Bad Request: /authentication/validate-email
[2024-02-26 21:00:56,096] 241 django.request - ERROR -Internal Server Error: /authentication/register
Traceback (most recent call last):
  File "C:\Users\DELL\Anaconda3\lib\site-packages\django\core\handlers\exception.py", line 55, in inner
    response = get_response(request)
  File "C:\Users\DELL\Anaconda3\lib\site-packages\django\core\handlers\base.py", line 197, in _get_response
    response = wrapped_callback(request, *callback_args, **callback_kwargs)
  File "C:\Users\DELL\Anaconda3\lib\site-packages\django\views\generic\base.py", line 104, in view
    return self.dispatch(request, *args, **kwargs)
  File "C:\Users\DELL\Anaconda3\lib\site-packages\django\views\generic\base.py", line 143, in dispatch
    return handler(request, *args, **kwargs)
  File "C:\Users\DELL\PycharmProjects\django\myproject\authentication\views.py", line 74, in post
    server.login(sender_email,password)
  File "C:\Users\DELL\Anaconda3\lib\smtplib.py", line 750, in login
    raise last_exception
  File "C:\Users\DELL\Anaconda3\lib\smtplib.py", line 739, in login
    (code, resp) = self.auth(
  File "C:\Users\DELL\Anaconda3\lib\smtplib.py", line 662, in auth
    raise SMTPAuthenticationError(code, resp)
smtplib.SMTPAuthenticationError: (535, b'5.7.8 Username and Password not accepted. For more information, go to\n5.7.8  https://support.google.com/mail/?p=BadCredentials jd9-20020a170903260900b001d974ffa1fcsm4148649plb.173 - gsmtp')
[2024-02-26 21:05:15,993] 266 django.utils.autoreload - INFO -C:\Users\DELL\PycharmProjects\django\myproject\authentication\views.py changed, reloading.
