[2024-02-26 08:53:53,041] 160 numexpr.utils - INFO -NumExpr defaulting to 4 threads.
[2024-02-26 09:05:22,653] 241 django.security.csrf - WARNING -Forbidden (CSRF token missing.): /tab
[2024-02-26 09:19:15,256] 241 django.request - WARNING -Not Found: /prediction/training
[2024-02-26 09:19:21,290] 241 django.request - WARNING -Not Found: /prediction/training
[2024-02-26 09:20:01,707] 241 django.request - WARNING -Not Found: /prediction/prediction
[2024-02-26 11:14:10,517] 241 django.request - ERROR -Internal Server Error: /registration
Traceback (most recent call last):
  File "C:\Users\DELL\Anaconda3\lib\site-packages\django\core\handlers\exception.py", line 55, in inner
    response = get_response(request)
  File "C:\Users\DELL\Anaconda3\lib\site-packages\django\core\handlers\base.py", line 197, in _get_response
    response = wrapped_callback(request, *callback_args, **callback_kwargs)
  File "C:\Users\DELL\PycharmProjects\django\myproject\trade\views.py", line 137, in registration
    myuser=User.objects.create_user(username,email,password)
  File "C:\Users\DELL\Anaconda3\lib\site-packages\django\contrib\auth\models.py", line 161, in create_user
    return self._create_user(username, email, password, **extra_fields)
  File "C:\Users\DELL\Anaconda3\lib\site-packages\django\contrib\auth\models.py", line 144, in _create_user
    raise ValueError("The given username must be set")
ValueError: The given username must be set
[2024-02-26 11:21:45,852] 241 django.request - WARNING -Not Found: /docs/5.3/assets/js/color-modes.js
[2024-02-26 11:21:45,890] 241 django.request - WARNING -Not Found: /docs/5.3/dist/js/bootstrap.bundle.min.js
[2024-02-26 11:22:23,219] 241 django.request - WARNING -Not Found: /docs/5.3/assets/js/color-modes.js
[2024-02-26 11:22:23,231] 241 django.request - WARNING -Not Found: /docs/5.3/dist/js/bootstrap.bundle.min.js
[2024-02-26 11:22:36,956] 241 django.request - ERROR -Internal Server Error: /registration
Traceback (most recent call last):
  File "C:\Users\DELL\Anaconda3\lib\site-packages\django\core\handlers\exception.py", line 55, in inner
    response = get_response(request)
  File "C:\Users\DELL\Anaconda3\lib\site-packages\django\core\handlers\base.py", line 197, in _get_response
    response = wrapped_callback(request, *callback_args, **callback_kwargs)
  File "C:\Users\DELL\PycharmProjects\django\myproject\trade\views.py", line 137, in registration
    myuser=User.objects.create_user(username,email,password)
  File "C:\Users\DELL\Anaconda3\lib\site-packages\django\contrib\auth\models.py", line 161, in create_user
    return self._create_user(username, email, password, **extra_fields)
  File "C:\Users\DELL\Anaconda3\lib\site-packages\django\contrib\auth\models.py", line 144, in _create_user
    raise ValueError("The given username must be set")
ValueError: The given username must be set
[2024-02-26 12:02:12,927] 266 django.utils.autoreload - INFO -C:\Users\DELL\PycharmProjects\django\myproject\trade\views.py changed, reloading.
